<?xml version="1.0" encoding="utf-8"?>
<!-- This URDF was automatically created by SolidWorks to URDF Exporter! Originally created by Stephen Brawner (brawner@gmail.com) 
     Commit Version: 1.6.0-4-g7f85cfe  Build Version: 1.6.7995.38578
     For more information, please see http://wiki.ros.org/sw_urdf_exporter -->
<robot
  name="Echo_Assem1.SLDASM">
  <link
    name="base_link">
    <inertial>
      <origin
        xyz="0.00088588 5.7031E-05 0.02478"
        rpy="0 0 0" />
      <mass
        value="0.99833" />
      <inertia
        ixx="0.0010305"
        ixy="-1.7168E-06"
        ixz="1.5313E-05"
        iyy="0.0035021"
        iyz="1.7459E-07"
        izz="0.0041088" />
    </inertial>
    <visual>
      <origin
        xyz="0 0 0"
        rpy="0 0 0" />
      <geometry>
        <mesh
          filename="package://Echo_Assem1.SLDASM/meshes/base_link.STL" />
      </geometry>
      <material
        name="">
        <color
          rgba="0.79216 0.81961 0.93333 1" />
      </material>
    </visual>
    <collision>
      <origin
        xyz="0 0 0"
        rpy="0 0 0" />
      <geometry>
        <mesh
          filename="package://Echo_Assem1.SLDASM/meshes/base_link.STL" />
      </geometry>
    </collision>
  </link>
  <link
    name="left_wheel_link">
    <inertial>
      <origin
        xyz="-1.5613E-16 -0.0072578 0"
        rpy="0 0 0" />
      <mass
        value="0.071063" />
      <inertia
        ixx="2.952E-05"
        ixy="-6.5589E-20"
        ixz="0"
        iyy="5.6596E-05"
        iyz="1.1271E-20"
        izz="2.952E-05" />
    </inertial>
    <visual>
      <origin
        xyz="0 0 0"
        rpy="0 0 0" />
      <geometry>
        <mesh
          filename="package://Echo_Assem1.SLDASM/meshes/left_wheel_link.STL" />
      </geometry>
      <material
        name="">
        <color
          rgba="0.79216 0.81961 0.93333 1" />
      </material>
    </visual>
    <collision>
      <origin
        xyz="0 0 0"
        rpy="0 0 0" />
      <geometry>
        <mesh
          filename="package://Echo_Assem1.SLDASM/meshes/left_wheel_link.STL" />
      </geometry>
    </collision>
  </link>
  <joint
    name="base_link_to_left_wheel"
    type="continuous">
    <origin
      xyz="-0.07 -0.02 0.05"
      rpy="-1.5708 0 -1.2335" />
    <parent
      link="base_link" />
    <child
      link="left_wheel_link" />
    <axis
      xyz="0 1 0" />
  </joint>
  <link
    name="right_wheel_link">
    <inertial>
      <origin
        xyz="-1.249E-16 -0.0072578 0"
        rpy="0 0 0" />
      <mass
        value="0.071063" />
      <inertia
        ixx="2.952E-05"
        ixy="-6.9916E-20"
        ixz="3.3881E-21"
        iyy="5.6596E-05"
        iyz="1.6149E-20"
        izz="2.952E-05" />
    </inertial>
    <visual>
      <origin
        xyz="0 0 0"
        rpy="0 0 0" />
      <geometry>
        <mesh
          filename="package://Echo_Assem1.SLDASM/meshes/right_wheel_link.STL" />
      </geometry>
      <material
        name="">
        <color
          rgba="0.79216 0.81961 0.93333 1" />
      </material>
    </visual>
    <collision>
      <origin
        xyz="0 0 0"
        rpy="0 0 0" />
      <geometry>
        <mesh
          filename="package://Echo_Assem1.SLDASM/meshes/right_wheel_link.STL" />
      </geometry>
    </collision>
  </link>
  <joint
    name="base_link_to_right_wheel"
    type="continuous">
    <origin
      xyz="-0.07 -0.02 -0.05"
      rpy="1.5708 0 -0.62035" />
    <parent
      link="base_link" />
    <child
      link="right_wheel_link" />
    <axis
      xyz="0 1 0" />
  </joint>
  <link
    name="caster_wheel">
    <inertial>
      <origin
        xyz="0 -2.0817E-17 0.0045"
        rpy="0 0 0" />
      <mass
        value="0.0036191" />
      <inertia
        ixx="1.3517E-07"
        ixy="-4.0433E-39"
        ixz="1.1099E-24"
        iyy="1.3517E-07"
        iyz="-5.3732E-22"
        izz="2.0846E-07" />
    </inertial>
    <visual>
      <origin
        xyz="0 0 0"
        rpy="0 0 0" />
      <geometry>
        <mesh
          filename="package://Echo_Assem1.SLDASM/meshes/caster_wheel.STL" />
      </geometry>
      <material
        name="">
        <color
          rgba="0.79216 0.81961 0.93333 1" />
      </material>
    </visual>
    <collision>
      <origin
        xyz="0 0 0"
        rpy="0 0 0" />
      <geometry>
        <mesh
          filename="package://Echo_Assem1.SLDASM/meshes/caster_wheel.STL" />
      </geometry>
    </collision>
  </link>
  <joint
    name="base_link_to_caster_wheel"
    type="fixed">
    <origin
      xyz="0.07 0.008 0"
      rpy="1.5708 -0.73937 3.1416" />
    <parent
      link="base_link" />
    <child
      link="caster_wheel" />
    <axis
      xyz="0 0 0" />
  </joint>
  <link
    name="camera_link">
    <inertial>
      <origin
        xyz="0.0024702 -1.2275E-17 0"
        rpy="0 0 0" />
      <mass
        value="0.00094737" />
      <inertia
        ixx="5.0737E-08"
        ixy="-1.7868E-23"
        ixz="2.4449E-25"
        iyy="6.9275E-09"
        iyz="7.8632E-15"
        izz="4.7598E-08" />
    </inertial>
    <visual>
      <origin
        xyz="0 0 0"
        rpy="0 0 0" />
      <geometry>
        <mesh
          filename="package://Echo_Assem1.SLDASM/meshes/camera_link.STL" />
      </geometry>
      <material
        name="">
        <color
          rgba="0.79216 0.81961 0.93333 1" />
      </material>
    </visual>
    <collision>
      <origin
        xyz="0 0 0"
        rpy="0 0 0" />
      <geometry>
        <mesh
          filename="package://Echo_Assem1.SLDASM/meshes/camera_link.STL" />
      </geometry>
    </collision>
  </link>
  <joint
    name="base_link_to_camera"
    type="fixed">
    <origin
      xyz="0.1 -0.049 0"
      rpy="1.5708 0 0" />
    <parent
      link="base_link" />
    <child
      link="camera_link" />
    <axis
      xyz="0 0 0" />
  </joint>
  <link
    name="lidar_link">
    <inertial>
      <origin
        xyz="0 0 0"
        rpy="0 0 0" />
      <mass
        value="0" />
      <inertia
        ixx="0"
        ixy="0"
        ixz="0"
        iyy="0"
        iyz="0"
        izz="0" />
    </inertial>
    <visual>
      <origin
        xyz="0 0 0"
        rpy="0 0 0" />
      <geometry>
        <mesh
          filename="package://Echo_Assem1.SLDASM/meshes/lidar_link.STL" />
      </geometry>
      <material
        name="">
        <color
          rgba="1 1 1 1" />
      </material>
    </visual>
    <collision>
      <origin
        xyz="0 0 0"
        rpy="0 0 0" />
      <geometry>
        <mesh
          filename="package://Echo_Assem1.SLDASM/meshes/lidar_link.STL" />
      </geometry>
    </collision>
  </link>
  <joint
    name="base_link_to_lidar"
    type="fixed">
    <origin
      xyz="0 -0.05 0"
      rpy="-1.5708 -0.38409 3.1416" />
    <parent
      link="base_link" />
    <child
      link="lidar_link" />
    <axis
      xyz="0 0 0" />
  </joint>
</robot>