<?xml version="1.0" encoding="utf-8"?>

<robot name="echo_v1" xmlns:xacro="http://www.ros.org/wiki/xacro">

  <!-- ========================= -->
  <!-- Global Properties & Macros -->
  <!-- ========================= -->


<!-- Include  gazebo control xacro -->
  <xacro:include filename="/home/cameron/Project_Echo/Educational/amr_ws/src/echo_sim_v1/urdf/gazebo_control.xacro"/>

<!-- Include materials xacro -->
  <xacro:include filename="/home/cameron/Project_Echo/Educational/amr_ws/src/echo_sim_v1/urdf/materials.xacro"/>

<!-- Include lidar xacro -->
  <xacro:include filename="/home/cameron/Project_Echo/Educational/amr_ws/src/echo_sim_v1/urdf/lidar.xacro"/>

<!-- Include camera xacro -->
  <!-- <xacro:include filename="/home/cameron/Project_Echo/Educational/amr_ws/src/echo_sim_v1/urdf/camera.xacro"/> -->


  <!-- Inertia Macros -->
  <xacro:macro name="inertial_sphere" params="mass radius *origin">
    <inertial>
      <xacro:insert_block name="origin"/>
      <mass value="${mass}" />
      <inertia ixx="${(2/5) * mass * (radius*radius)}" ixy="0.0" ixz="0.0"
               iyy="${(2/5) * mass * (radius*radius)}" iyz="0.0"
               izz="${(2/5) * mass * (radius*radius)}" />
    </inertial>
  </xacro:macro>  

  <xacro:macro name="inertial_box" params="mass x y z *origin">
    <inertial>
      <xacro:insert_block name="origin"/>
      <mass value="${mass}" />
      <inertia ixx="${(1/12) * mass * (y*y+z*z)}" ixy="0.0" ixz="0.0"
               iyy="${(1/12) * mass * (x*x+z*z)}" iyz="0.0"
               izz="${(1/12) * mass * (x*x+y*y)}" />
    </inertial>
  </xacro:macro>

  <xacro:macro name="inertial_cylinder" params="mass length radius *origin">
    <inertial>
      <xacro:insert_block name="origin"/>
      <mass value="${mass}" />
      <inertia ixx="${(1/12) * mass * (3*radius*radius + length*length)}" ixy="0.0" ixz="0.0"
               iyy="${(1/12) * mass * (3*radius*radius + length*length)}" iyz="0.0"
               izz="${(1/2) * mass * (radius*radius)}" />
    </inertial>
  </xacro:macro>

  <!-- ========================= -->
  <!-- Links and Joints -->
  <!-- ========================= -->

  <!-- Base link (empty root) -->
  <link name="base_link"/>


  <!-- Base Footprint Link -->
  <joint name="base_footprint_joint" type="fixed">
    <parent link="base_link"/>
    <child link="base_footprint"/>
    <origin xyz="0 0 0" rpy="0 0 0"/> 
  </joint>

  <link name="base_footprint"/> 


  <!-- Chassis -->
  <joint name="chassis_joint" type="fixed">
    <parent link="base_link"/>
    <child link="chassis"/>
    <origin xyz="-0.1 0 0"/>
  </joint>

  <link name="chassis">
    <visual>
      <origin xyz="0.15 0 0.075"/>
      <geometry>
        <box size="0.4 0.3 0.1"/>
      </geometry>
      <material name="red"/>
    </visual>
    <collision>
      <origin xyz="0.15 0 0.075"/>
      <geometry>
        <box size="0.4 0.3 0.1"/>
      </geometry>
    </collision>
    <xacro:inertial_box mass="0.5" x="0.4" y="0.3" z="0.1">
      <origin xyz="0.15 0 0.075" rpy="0 0 0"/>
    </xacro:inertial_box>
  </link>

  <gazebo reference="chassis">
    <material>Gazebo/Red</material>
  </gazebo>

  <!-- Left Wheel -->
  <joint name="left_wheel_joint" type="continuous">
    <parent link="base_link"/>
    <child link="left_wheel"/>
    <origin xyz="-0.07 0.175 0" rpy="0 0 0"/>
    <axis xyz="0 1 0"/>
  </joint>

  <link name="left_wheel">
    <visual>
      <origin xyz="0 0 0" rpy="${pi/2} 0 0"/> 
      <geometry>
        <cylinder radius="0.05" length="0.04"/>
      </geometry>
      <material name="dark_grey"/>
    </visual>
    <collision>
      <origin xyz="0 0 0" rpy="${pi/2} 0 0"/> 
      <geometry>
        <cylinder radius="0.05" length="0.04"/>
      </geometry>
    </collision>
    <xacro:inertial_cylinder mass="0.1" length="0.04" radius="0.05">
      <origin xyz="0 0 0" rpy="0 0 0"/>
    </xacro:inertial_cylinder>
  </link>

  <gazebo reference="left_wheel">
    <material>Gazebo/DarkGrey</material>
  </gazebo>

  <!-- Right Wheel -->
  <joint name="right_wheel_joint" type="continuous">
    <parent link="base_link"/>
    <child link="right_wheel"/>
    <origin xyz="-0.07 -0.175 0" rpy="0 0 0"/>
    <axis xyz="0 1 0"/> 
  </joint>

  <link name="right_wheel">
    <visual>
      <origin xyz="0 0 0" rpy="${pi/2} 0 0"/> 
      <geometry>
        <cylinder radius="0.05" length="0.04"/>
      </geometry>
      <material name="dark_grey"/>
    </visual>
    <collision>
      <origin xyz="0 0 0" rpy="${pi/2} 0 0"/>
      <geometry>
        <cylinder radius="0.05" length="0.04"/>
      </geometry>
    </collision>
    <xacro:inertial_cylinder mass="0.1" length="0.04" radius="0.05">
      <origin xyz="0 0 0" rpy="0 0 0"/>
    </xacro:inertial_cylinder>
  </link>

  <gazebo reference="right_wheel">
    <material>Gazebo/DarkGrey</material>
  </gazebo>

  <!-- Caster Wheel -->
  <joint name="caster_wheel_joint" type="fixed">
    <parent link="chassis"/>
    <child link="caster_wheel"/>
    <origin xyz="0.285 0 0"/>
  </joint>

  <link name="caster_wheel">
    <visual>
      <geometry>
        <sphere radius="0.05"/>
      </geometry>
      <material name="dark_grey"/>
    </visual>
    <collision>
      <geometry>
        <sphere radius="0.05"/>
      </geometry>
    </collision>
    <xacro:inertial_sphere mass="0.1" radius="0.05">
      <origin xyz="0 0 0" rpy="0 0 0"/>
    </xacro:inertial_sphere>
  </link>

  <gazebo reference="caster_wheel">
    <material>Gazebo/Grey</material>
    <mu1 value="0.001"/>
    <mu2 value="0.001"/>
  </gazebo>

<!-- Lidar -->
<joint name="laser_joint" type="fixed">
        <parent link="chassis"/>
        <child link="laser_frame"/>
        <origin xyz="0.2 0 0.15" rpy="0 0 0"/>
</joint>

    <link name="laser_frame">
        <visual>
            <geometry>
                <cylinder radius="0.04" length="0.05"/>
            </geometry>
            <material name="silver"/>
        </visual>
        <collision>
            <geometry>
                <cylinder radius="0.04" length="0.05"/>
            </geometry>
        </collision>
        <xacro:inertial_cylinder mass="0.1" length="0.05" radius="0.04">
            <origin xyz="0 0 0" rpy="0 0 0"/>
        </xacro:inertial_cylinder>
    </link>

    <gazebo reference="laser_frame">
        <material>Gazebo/Grey</material>
    </gazebo>

  <!-- Camera -->
  <!-- <joint name="camera_joint" type="fixed"> 
        <child link="camera_link"/>
        <origin xyz="0.4 0 0.15" rpy="0 0 0"/>
  </joint>
    
  <link name="camera_link">
      <visual>
        <geometry>
          <box size="0.015 0.03 0.03"/>
        </geometry>
        <material name="silver"/>
      </visual>
  </link>

  <joint name="camera_optical_joint" type="fixed"> 
        <parent link="camera_link"/>
        <child link="camera_link_optical"/>
        <origin xyz="0 0 0" rpy="${-pi/2} 0 ${-pi/2}"/>
  </joint>  

  <link name="camera_link_optical"></link>

  <gazebo reference="camera_link">
    <material>Gazebo/Grey</material>
  </gazebo> -->


</robot>
