<?xml version="1.0" ?>
<sdf version="1.8">
  <world name="echo_world">
    <!-- Physics -->
    <physics name="1ms" type="ignored">
      <max_step_size>0.001</max_step_size>
      <real_time_factor>1.0</real_time_factor>
    </physics>

    <!-- Plugins -->
    <plugin filename="libignition-gazebo-physics-system.so" name="ignition::gazebo::systems::Physics"/>
    <plugin filename="libignition-gazebo-user-commands-system.so" name="ignition::gazebo::systems::UserCommands"/>
    <plugin filename="libignition-gazebo-scene-broadcaster-system.so" name="ignition::gazebo::systems::SceneBroadcaster"/>

    <!-- Lighting -->
    <light type="directional" name="sun">
      <cast_shadows>true</cast_shadows>
      <pose>0 0 10 0 0 0</pose>
      <diffuse>0.8 0.8 0.8 1</diffuse>
      <specular>0.2 0.2 0.2 1</specular>
      <attenuation>
        <range>1000</range>
        <constant>0.9</constant>
        <linear>0.01</linear>
        <quadratic>0.001</quadratic>
      </attenuation>
      <direction>-0.5 0.1 -0.9</direction>
    </light>

    <!-- Ground Plane -->
    <model name="ground_plane">
      <static>true</static>
      <link name="link">
        <collision name="collision">
          <geometry>
            <plane>
              <normal>0 0 1</normal>
            </plane>
          </geometry>
        </collision>
        <visual name="visual">
          <geometry>
            <plane>
              <normal>0 0 1</normal>
              <size>100 100</size>
            </plane>
          </geometry>
          <material>
            <ambient>0.8 0.8 0.8 1</ambient>
            <diffuse>0.8 0.8 0.8 1</diffuse>
            <specular>0.8 0.8 0.8 1</specular>
          </material>
        </visual>
      </link>
    </model>

    <model name='echo_v1'>
    <link name='base_footprint'>
      <inertial>
        <pose>0.001202 0.024079 0.021371 0 -0 0</pose>
        <mass>1.02739</mass>
        <inertia>
          <ixx>0.00113964</ixx>
          <ixy>2.31307e-05</ixy>
          <ixz>1.8698e-06</ixz>
          <iyy>0.00422753</iyy>
          <iyz>3.5146e-05</iyz>
          <izz>0.00355148</izz>
        </inertia>
      </inertial>
      <collision name='base_footprint_fixed_joint_lump__base_link_collision'>
        <pose>0 0 0.02 -1.5708 0 0</pose>
        <geometry>
          <mesh>
            <scale>1 1 1</scale>
            <uri>model://echo_sim_v1/meshes/base_link.STL</uri>
          </mesh>
        </geometry>
      </collision>
      <collision name='base_footprint_fixed_joint_lump__camera_link_collision_1'>
        <pose>0.1 0 0.069 0 -0 0</pose>
        <geometry>
          <mesh>
            <scale>1 1 1</scale>
            <uri>model://echo_sim_v1/meshes/camera_link.STL</uri>
          </mesh>
        </geometry>
      </collision>
      <collision name='base_footprint_fixed_joint_lump__caster_wheel_link_collision_2'>
        <pose>0.07 -0 0.012 -3.14158 2e-06 1.84679</pose>
        <geometry>
          <mesh>
            <scale>1 1 1</scale>
            <uri>model://echo_sim_v1/meshes/caster_wheel_link.STL</uri>
          </mesh>
        </geometry>
      </collision>
      <collision name='base_footprint_fixed_joint_lump__lidar_link_collision_3'>
        <pose>0 0 0.07 0 -1e-06 -0.30388</pose>
        <geometry>
          <mesh>
            <scale>1 1 1</scale>
            <uri>model://echo_sim_v1/meshes/lidar_link.STL</uri>
          </mesh>
        </geometry>
      </collision>
      <visual name='base_footprint_fixed_joint_lump__base_link_visual'>
        <pose>0 0 0.02 -1.5708 0 0</pose>
        <geometry>
          <mesh>
            <scale>1 1 1</scale>
            <uri>model://echo_sim_v1/meshes/base_link.STL</uri>
          </mesh>
        </geometry>
      </visual>
      <visual name='base_footprint_fixed_joint_lump__camera_link_visual_1'>
        <pose>0.1 0 0.069 0 -0 0</pose>
        <geometry>
          <mesh>
            <scale>1 1 1</scale>
            <uri>model://echo_sim_v1/meshes/camera_link.STL</uri>
          </mesh>
        </geometry>
      </visual>
      <visual name='base_footprint_fixed_joint_lump__caster_wheel_link_visual_2'>
        <pose>0.07 -0 0.012 -3.14158 2e-06 1.84679</pose>
        <geometry>
          <mesh>
            <scale>1 1 1</scale>
            <uri>model://echo_sim_v1/meshes/caster_wheel_link.STL</uri>
          </mesh>
        </geometry>
      </visual>
      <visual name='base_footprint_fixed_joint_lump__lidar_link_visual_3'>
        <pose>0 0 0.07 0 -1e-06 -0.30388</pose>
        <geometry>
          <mesh>
            <scale>1 1 1</scale>
            <uri>model://echo_sim_v1/meshes/lidar_link.STL</uri>
          </mesh>
        </geometry>
      </visual>
    </link>
    <joint name='base_link_to_left_wheel' type='revolute'>
      <pose relative_to='base_footprint'>-0.07 0.05 0.04 0.785394 -1.57079 2.35619</pose>
      <parent>base_footprint</parent>
      <child>left_wheel_link</child>
      <axis>
        <xyz>0 -1 0</xyz>
        <limit>
          <lower>-1e+16</lower>
          <upper>1e+16</upper>
        </limit>
        <dynamics>
          <spring_reference>0</spring_reference>
          <spring_stiffness>0</spring_stiffness>
        </dynamics>
      </axis>
    </joint>
    <link name='left_wheel_link'>
      <pose relative_to='base_link_to_left_wheel'>0 0 0 0 -0 0</pose>
      <inertial>
        <pose>-0 0.0075 0 0 -0 0</pose>
        <mass>0.073711</mass>
        <inertia>
          <ixx>3.0207e-05</ixx>
          <ixy>-3.1866e-38</ixy>
          <ixz>1.075e-37</ixz>
          <iyy>5.7735e-05</iyy>
          <iyz>1.0613e-38</iyz>
          <izz>3.0207e-05</izz>
        </inertia>
      </inertial>
      <collision name='left_wheel_link_collision'>
        <pose>0 0 0 0 -0 0</pose>
        <geometry>
          <mesh>
            <scale>1 1 1</scale>
            <uri>model://echo_sim_v1/meshes/left_wheel_link.STL</uri>
          </mesh>
        </geometry>
      </collision>
      <visual name='left_wheel_link_visual'>
        <pose>0 0 0 0 -0 0</pose>
        <geometry>
          <mesh>
            <scale>1 1 1</scale>
            <uri>model://echo_sim_v1/meshes/left_wheel_link.STL</uri>
          </mesh>
        </geometry>
      </visual>
    </link>
    <joint name='base_link_to_right_wheel' type='revolute'>
      <pose relative_to='base_footprint'>-0.07 -0.05 0.04 0 -0 0</pose>
      <parent>base_footprint</parent>
      <child>right_wheel_link</child>
      <axis>
        <xyz>0 1 0</xyz>
        <limit>
          <lower>-1e+16</lower>
          <upper>1e+16</upper>
        </limit>
        <dynamics>
          <spring_reference>0</spring_reference>
          <spring_stiffness>0</spring_stiffness>
        </dynamics>
      </axis>
    </joint>
    <link name='right_wheel_link'>
      <pose relative_to='base_link_to_right_wheel'>0 0 0 0 -0 0</pose>
      <inertial>
        <pose>-0 -0.0075 0 0 -0 0</pose>
        <mass>0.073711</mass>
        <inertia>
          <ixx>3.0207e-05</ixx>
          <ixy>-3.1866e-38</ixy>
          <ixz>1.075e-37</ixz>
          <iyy>5.7735e-05</iyy>
          <iyz>1.0613e-38</iyz>
          <izz>3.0207e-05</izz>
        </inertia>
      </inertial>
      <collision name='right_wheel_link_collision'>
        <pose>0 0 0 0 -0 0</pose>
        <geometry>
          <mesh>
            <scale>1 1 1</scale>
            <uri>model://echo_sim_v1/meshes/right_wheel_link.STL</uri>
          </mesh>
        </geometry>
      </collision>
      <visual name='right_wheel_link_visual'>
        <pose>0 0 0 0 -0 0</pose>
        <geometry>
          <mesh>
            <scale>1 1 1</scale>
            <uri>model://echo_sim_v1/meshes/right_wheel_link.STL</uri>
          </mesh>
        </geometry>
      </visual>
    </link>
  </model>

    <!-- Triggered Keypress Plugins -->
    <plugin filename="libignition-gazebo-triggered-publisher-system.so"
            name="ignition::gazebo::systems::TriggeredPublisher">
      <input type="ignition.msgs.Int32" topic="/keyboard/keypress">
        <match field="data">16777235</match>
      </input>
      <output type="ignition.msgs.Twist" topic="/cmd_vel">
        linear: {x: 0.5}, angular: {z: 0.0}
      </output>
    </plugin>

    <plugin filename="libignition-gazebo-triggered-publisher-system.so"
            name="ignition::gazebo::systems::TriggeredPublisher">
      <input type="ignition.msgs.Int32" topic="/keyboard/keypress">
        <match field="data">16777237</match>
      </input>
      <output type="ignition.msgs.Twist" topic="/cmd_vel">
        linear: {x: -0.5}, angular: {z: 0.0}
      </output>
    </plugin>

    <plugin filename="libignition-gazebo-triggered-publisher-system.so"
            name="ignition::gazebo::systems::TriggeredPublisher">
      <input type="ignition.msgs.Int32" topic="/keyboard/keypress">
        <match field="data">16777236</match>
      </input>
      <output type="ignition.msgs.Twist" topic="/cmd_vel">
        linear: {x: 0.0}, angular: {z: -0.5}
      </output>
    </plugin>

    <plugin filename="libignition-gazebo-triggered-publisher-system.so"
            name="ignition::gazebo::systems::TriggeredPublisher">
      <input type="ignition.msgs.Int32" topic="/keyboard/keypress">
        <match field="data">16777234</match>
      </input>
      <output type="ignition.msgs.Twist" topic="/cmd_vel">
        linear: {x: 0.0}, angular: {z: 0.5}
      </output>
    </plugin>
  </world>
</sdf>
